Workbook

Sheet BOQ
A1: DG-T06 Type 06 - Rendered double garage - turnkey kit price + BOQ (Leeds / Yorkshire, ex VAT)
A2: SUPPLY SCOPE: the Nudura ICF formwork + accessories (section A) are our FIXED price. Every other package (section B) is the turnkey-kit BOQ at indicative Leeds / Yorkshire Q4 2026 rates - supplied in good faith, every rate editable, to be checked by the relevant professional and priced by the contractor. All figures ex VAT unless stated. QUOTATION - NOT FOR CONSTRUCTION.
A4: Install rates built from GBP/h | B4: 34
A5: OH&P % | B5: 15
A6: Contingency % | B6: 10
A7: VAT % | B7: 20
A9: A. NUDURA SUPPLY - FIXED PRICE (BuildEase / Tremco CPG)
A10: Item | B10: SKU | C10: Qty | D10: Unit | E10: Order | F10: Rate | G10: Per | H10: Total | I10: Note
A11: Nudura 6in Standard straight form (pre-cut) | B11: NUS-I0096-06-PC | C11: 58 | D11: nr | E11: 20 x 3 | F11: 149.37 | G11: box of 3 | H11: 2987.4 | I11: every form from the populated model, Nudura Bond, no stack joints
A12: Nudura 6in Standard 90 deg corner form (pre-cut) | B12: NUS-I0090-06-PC | C12: 20 | D12: nr | E12: 4 x 6 | F12: 154.41 | G12: box of 6 | H12: 617.64
A13: End caps 152 mm (6in) - opening jambs | B13: NUS-A0ECF-06 | C13: 28 | D13: nr | E13: 1 x 40 | F13: 105.84 | G13: box of 40 | H13: 105.84
A14: Lintel closures 152 mm (6in) - heads + sills | B14: NUS-PLINT-06 | C14: 42 | D14: nr | E14: 1 x 60 | F14: 181.44 | G14: box of 60 | H14: 181.44 | I14: 3 per lintel piece
A15: Spray foam (1 can per 22 forms) | B15: NUS-SF-BOX | C15: 4 | D15: nr | E15: 1 x 12 | F15: 75.6 | G15: box of 12 | H15: 75.6
A16: Fibre tape (1 roll per 50 forms) | B16: NUS-FT-BOX | C16: 2 | D16: nr | E16: 1 x 10 | F16: 52.5 | G16: box of 10 | H16: 52.5
A17: Protective tape | B17: NUS-PT-BOX | C17: 1 | D17: nr | E17: 1 x 4 | F17: 33.6 | G17: box of 4 | H17: 33.6
A18: Bracing + alignment hire (1 stillage x 1 wk) | B18: ALIGN | C18: 1 | D18: stillage | E18: 1 weeks | F18: 80 | G18: stillage | H18: 80 | I18: hire = the ICF install only: 1 d install + 1 pour + 1 cure + 1 strike = 4 working days -> 1 wk
A19: BuildEase pre-cut service (setup + per form + cuts) | B19: PRECUT | C19: 78 | D19: forms | E19: 44 cut forms | H19: 433 | I19: GBP 350 setup + 0.50 / form + GBP 1 / m cut (standard type - modelling included)
A20: Haulage - Tankersley S75 3DH to Leeds (<= 40 miles, 1 artic) | B20: HAUL | C20: 1 | D20: load | F20: 335.27 | G20: load | H20: 335.27
G21: Supply total | H21: =SUM(H11:H20)
A23: B. TURNKEY-KIT BOQ - SUMMARY OF BILLS (each bill on its own sheet; edit the yellow cells there)
B24: Bill 1 - Preliminaries | I24: ='Bill 1'!I6
B25: Bill 2 - Groundworks + substructure | I25: ='Bill 2'!I14
B26: Bill 3 - ICF walls (install + concrete) | I26: ='Bill 3'!I10
B27: Bill 4 - Roof structure + floors (carpentry: supply + install incl. fixings) | I27: ='Bill 4'!I17
B28: Bill 5 - Roof coverings + rainwater goods | I28: ='Bill 5'!I13
B29: Bill 6 - External wall finish | I29: ='Bill 6'!I10
B30: Bill 7 - Opening schedule (doors + windows) | I30: ='Bill 7'!I8
B31: Bill 8 - Electrical installation | I31: ='Bill 8'!I5
B32: Bill 9 - Design + approvals (provisional) | I32: ='Bill 9'!I7
H33: BOQ net | I33: =I24+I25+I26+I27+I28+I29+I30+I31+I32
H34: BOQ + OH&P | I34: =I33*(1+$B$5/100)
H36: TOTAL NET (A + B) | I36: =H21+I34
H37: + contingency | I37: =I36*(1+$B$6/100)
H38: TOTAL inc VAT | I38: =I37*(1+$B$7/100)
A40: C. PROGRAMME (working days)
B41: Site setup + setting out | C41: 0.5 | D41: days | J41: welfare, skip, set out the raft
B42: Below ground - excavation, muck away, drainage | C42: 2.7 | D42: days | J42: 2 operatives + excavator
B43: Footings / substructure - hardcore, DPM, mesh, starter bars | C43: 1 | D43: days
B44: Raft pour + power float | C44: 1 | D44: days | J44: pump on site
B45: Raft cure before the ICF | C45: 3 | D45: days | J45: minimum before standing the forms (7 days before full load)
...

Sheet Bill 1
A1: DG-T06 Type 06 - Rendered double garage - Bill 1 - Preliminaries
A3: Ref | B3: Item | C3: Qty | D3: Unit | E3: Supply rate | F3: Install rate | G3: Supply | H3: Install | I3: Total | J3: Source / note
A4: 1.1 | B4: Site setup, welfare, skip, setting out | C4: 1 | D4: item | E4: 650 | F4: 272 | G4: =C4*E4 | H4: =C4*F4 | I4: =G4+H4 | J4: NGR prelims 950 - site setup, welfare, skip, setting out (single garage)
A5: 1.2 | B5: Access scaffold / towers | C5: 1 | D5: item | E5: 480 | F5: 136 | G5: =C5*E5 | H5: =C5*F5 | I5: =G5+H5 | J5: MKT tower / trestle hire 4 wk, single storey
H6: Bill total | I6: =SUM(I4:I5)

Sheet Bill 2
A1: DG-T06 Type 06 - Rendered double garage - Bill 2 - Groundworks + substructure
A3: Ref | B3: Item | C3: Qty | D3: Unit | E3: Supply rate | F3: Install rate | G3: Supply | H3: Install | I3: Total | J3: Source / note
A4: 2.1 | B4: Excavate raft + thickened edge (reduce level 402 + edge to 500) | C4: 17.32 | D4: m3 | E4: 18 | F4: 11.9 | G4: =C4*E4 | H4: =C4*F4 | I4: =G4+H4 | J4: NGR dig 32/m3 split plant / labour
A5: 2.2 | B5: Muck away (bulked x1.25) | C5: 21.64 | D5: m3 | E5: 52 | F5: 0 | G5: =C5*E5 | H5: =C5*F5 | I5: =G5+H5 | J5: NGR
A6: 2.3 | B6: RWG drainage - short run to soakaway / connection | C6: 1 | D6: item | E6: 420 | F6: 340 | G6: =C6*E6 | H6: =C6*F6 | I6: =G6+H6 | J6: MKT RWG to soakaway / short connection
A7: 2.4 | B7: MOT Type 1 hardcore 150, compacted | C7: 3.86 | D7: m3 | E7: 48 | F7: 17 | G7: =C7*E7 | H7: =C7*F7 | I7: =G7+H7 | J7: NGR MOT Type 1
A8: 2.5 | B8: Sand blinding + 1200g DPM | C8: 43.34 | D8: m2 | E8: 5.3 | F8: 2.04 | G8: =C8*E8 | H8: =C8*F8 | I8: =G8+H8 | J8: NGR DPM 1.8 + sand blinding 3.5
A9: 2.6 | B9: A393 mesh top + bottom (laps incl.) | C9: 8 | D9: sheet | E9: 70 | F9: 11.9 | G9: =C9*E9 | H9: =C9*F9 | I9: =G9+H9 | J9: NGR A393 4.8 x 2.4
A10: 2.7 | B10: Starter bars T12 @ 600 into the ICF + edge bars | C10: 0.13 | D10: t | E10: 1250 | F10: 952 | G10: =C10*E10 | H10: =C10*F10 | I10: =G10+H10 | J10: NGR rebar + fixing 28 h/t
A11: 2.8 | B11: C32/40 raft concrete 200 + thickened edge | C11: 11.29 | D11: m3 | E11: 152 | F11: 40.8 | G11: =C11*E11 | H11: =C11*F11 | I11: =G11+H11 | J11: NGR C32/40
A12: 2.9 | B12: Concrete pump - raft pour | C12: 1 | D12: pour | E12: 650 | F12: 0 | G12: =C12*E12 | H12: =C12*F12 | I12: =G12+H12 | J12: NGR concrete pump per pour
A13: 2.10 | B13: Power float finish (garage floor, fall to the door) | C13: 39.4 | D13: m2 | E13: 1.5 | F13: 2.72 | G13: =C13*E13 | H13: =C13*F13 | I13: =G13+H13 | J13: MKT
H14: Bill total | I14: =SUM(I4:I13)

Sheet Bill 3
A1: DG-T06 Type 06 - Rendered double garage - Bill 3 - ICF walls (install + concrete)
A3: Ref | B3: Item | C3: Qty | D3: Unit | E3: Supply rate | F3: Install rate | G3: Supply | H3: Install | I3: Total | J3: Source / note
A4: 3.1 | B4: Stand the Nudura forms (78 forms, 4.3 min / form): set-out, bracing + alignment, rebar, end caps / lintels | C4: 1 | D4: gang-day | E4: 0 | F4: 816 | G4: =C4*E4 | H4: =C4*F4 | I4: =G4+H4 | J4: BOQ Builder 4.3 min per block x 3-man gang
A5: 3.2 | B5: Pour the ICF core (walls + gables, one day), 4-man pour gang | C5: 1 | D5: gang-day | E5: 0 | F5: 1088 | G5: =C5*E5 | H5: =C5*F5 | I5: =G5+H5 | J5: BOQ Builder 4.3 min per block x 3-man gang
A6: 3.3 | B6: Strike the bracing + alignment system (after 1 day cure) | C6: 1 | D6: gang-day | E6: 0 | F6: 816 | G6: =C6*E6 | H6: =C6*F6 | I6: =G6+H6 | J6: BOQ Builder 4.3 min per block x 3-man gang
A7: 3.4 | B7: Wall reinforcement T12 (vertical @ 600, horizontal alternate courses) + lintel bars - supply (fixing in the install line) | C7: 0.22 | D7: t | E7: 1250 | F7: 0 | G7: =C7*E7 | H7: =C7*F7 | I7: =G7+H7 | J7: NGR rebar + fixing 28 h/t
A8: 3.5 | B8: C32/40 core concrete 6in - supply (placing in the install line) | C8: 7.6 | D8: m3 | E8: 152 | F8: 0 | G8: =C8*E8 | H8: =C8*F8 | I8: =G8+H8 | J8: NGR C32/40 + pour 1.2 h/m3
A9: 3.6 | B9: Concrete pump - ICF pour | C9: 1 | D9: pour | E9: 650 | F9: 0 | G9: =C9*E9 | H9: =C9*F9 | I9: =G9+H9 | J9: NGR concrete pump per pour
H10: Bill total | I10: =SUM(I4:I9)

Sheet Bill 4
A1: DG-T06 Type 06 - Rendered double garage - Bill 4 - Roof structure + floors (carpentry: supply + install incl. fixings)
A3: Ref | B3: Item | C3: Qty | D3: Unit | E3: Supply rate | F3: Install rate | G3: Supply | H3: Install | I3: Total | J3: Source / note
A4: 4.1 | B4: Wall plate 47 x 150 C24 treated on the eaves walls (bedded) | C4: 12.15 | D4: m | E4: 5.6 | F4: 8.5 | G4: =C4*E4 | H4: =C4*F4 | I4: =G4+H4 | J4: NGR C24 47x150 4.25/m + straps / anchors
A5: 4.2 | B5: Wall plate fixings - M12 anchors into the ICF core @ 1,200 + washers | C5: 13 | D5: nr | E5: 3.2 | F5: 5.1 | G5: =C5*E5 | H5: =C5*F5 | I5: =G5+H5 | J5: MKT M12 anchor / resin stud into the ICF core @ 1,200 + washer
A6: 4.3 | B6: Trussed rafters (fink) @600, span 6.48 m | C6: 10 | D6: nr | E6: 174.15 | F6: 25.5 | G6: =C6*E6 | H6: =C6*F6 | I6: =G6+H6 | J6: TLS 38 + 21/m span (mat computed per type)
A7: 4.4 | B7: Binders + diagonal bracing 25 x 100 | C7: 37.09 | D7: m | E7: 1.35 | F7: 2.72 | G7: =C7*E7 | H7: =C7*F7 | I7: =G7+H7 | J7: TLS 25x100 binders + diagonal bracing
A8: 4.5 | B8: Truss clips to the wall plate (2 per truss) | C8: 20 | D8: nr | E8: 1.1 | F8: 2.72 | G8: =C8*E8 | H8: =C8*F8 | I8: =G8+H8 | J8: MKT truss clip to the wall plate
A9: 4.6 | B9: Twist / holding-down straps (2 per truss) | C9: 20 | D9: nr | E9: 1.4 | F9: 3.4 | G9: =C9*E9 | H9: =C9*F9 | I9: =G9+H9 | J9: MKT twist / holding-down strap
A10: 4.7 | B10: PROVISIONAL floors / decking - 18 P5 loft storage boards on the ceiling ties (storage-rated trusses) | C10: 16.27 | D10: m2 | E10: 9.5 | F10: 8.5 | G10: =C10*E10 | H10: =C10*F10 | I10: =G10+H10 | J10: MKT 18 P5 loft boards (PROVISIONAL - storage trusses)
A11: 4.8 | B11: PROVISIONAL - 47 x 72 noggins under the board edges | C11: 27.12 | D11: m | E11: 1.9 | F11: 3.4 | G11: =C11*E11 | H11: =C11*F11 | I11: =G11+H11 | J11: MKT 47 x 72 C16 noggins
A12: 4.9 | B12: PROVISIONAL - deck screws | C12: 16.27 | D12: m2 | E12: 0.6 | F12: 0 | G12: =C12*E12 | H12: =C12*F12 | I12: =G12+H12 | J12: MKT deck screws
A13: 4.10 | B13: PROVISIONAL - insulated loft hatch + folding ladder | C13: 1 | D13: nr | E13: 185 | F13: 68 | G13: =C13*E13 | H13: =C13*F13 | I13: =G13+H13 | J13: MKT insulated loft hatch + folding ladder (PROVISIONAL)
A14: 4.11 | B14: Gable ladders (barge, rails, outriggers 47 x 72) | C14: 44.87 | D14: m | E14: 1.35 | F14: 2.72 | G14: =C14*E14 | H14: =C14*F14 | I14: =G14+H14 | J14: TLS 25x100 binders + diagonal bracing
A15: 4.12 | B15: Gable lateral restraint straps @ 2 m to the trusses / rafters (both gables) | C15: 8 | D15: nr | E15: 4.5 | F15: 6.8 | G15: =C15*E15 | H15: =C15*F15 | I15: =G15+H15 | J15: MKT galv lateral restraint strap 30 x 5 x 1000 (BS EN 845-1)
A16: 4.13 | B16: Carpentry sundries - nails, screws, framing anchors | C16: 1 | D16: item | E16: 45 | F16: 0 | G16: =C16*E16 | H16: =C16*F16 | I16: =G16+H16 | J16: MKT nails, screws, framing anchors
H17: Bill total | I17: =SUM(I4:I16)

Sheet Bill 5
A1: DG-T06 Type 06 - Rendered double garage - Bill 5 - Roof coverings + rainwater goods
A3: Ref | B3: Item | C3: Qty | D3: Unit | E3: Supply rate | F3: Install rate | G3: Supply | H3: Install | I3: Total | J3: Source / note
A4: 5.1 | B4: Breathable roofing membrane (laps incl.) | C4: 54.8 | D4: m2 | E4: 1.1 | F4: 1.02 | G4: =C4*E4 | H4: =C4*F4 | I4: =G4+H4 | J4: TLS breather membrane
A5: 5.2 | B5: Treated battens 25 x 50 @ 345 gauge | C5: 168.4 | D5: m | E5: 0.85 | F5: 0.68 | G5: =C5*E5 | H5: =C5*F5 | I5: =G5+H5 | J5: TLS 25x50 treated
A6: 5.3 | B6: Marley Modern smooth grey tiles (drawn: 484, +3% breakage) | C6: 499 | D6: nr | E6: 1.48 | F6: 1.19 | G6: =C6*E6 | H6: =C6*F6 | I6: =G6+H6 | J6: WEB Marley Modern smooth grey ex VAT; ~0.37 h/m2 roofer
A7: 5.4 | B7: Dry ridge + half-round ridge tiles (15 drawn) | C7: 6.38 | D7: m | E7: 24 | F7: 11.9 | G7: =C7*E7 | H7: =C7*F7 | I7: =G7+H7 | J7: MKT dry ridge kit + half-round ridge tiles
A8: 5.5 | B8: Dry verge units | C8: 14.96 | D8: m | E8: 14 | F8: 6.8 | G8: =C8*E8 | H8: =C8*F8 | I8: =G8+H8 | J8: MKT dry verge units
A9: 5.6 | B9: uPVC fascia 22 x 200 + vented soffit | C9: 12.75 | D9: m | E9: 16 | F9: 11.9 | G9: =C9*E9 | H9: =C9*F9 | I9: =G9+H9 | J9: TLS uPVC fascia / soffit
A10: 5.7 | B10: uPVC barge boards 22 x 225 | C10: 14.96 | D10: m | E10: 14 | F10: 10.2 | G10: =C10*E10 | H10: =C10*F10 | I10: =G10+H10 | J10: TLS uPVC barge board
A11: 5.8 | B11: Half-round gutter 112 black + fittings | C11: 12.75 | D11: m | E11: 11 | F11: 6.8 | G11: =C11*E11 | H11: =C11*F11 | I11: =G11+H11 | J11: TLS half-round gutter + brackets
A12: 5.9 | B12: Downpipe sets 68 round black: swan neck to the outlet, clipped to the side wall (6 clips), shoe | C12: 2 | D12: nr | E12: 38 | F12: 34 | G12: =C12*E12 | H12: =C12*F12 | I12: =G12+H12 | J12: TLS downpipe set
H13: Bill total | I13: =SUM(I4:I12)

Sheet Bill 6
A1: DG-T06 Type 06 - Rendered double garage - Bill 6 - External wall finish
A3: Ref | B3: Item | C3: Qty | D3: Unit | E3: Supply rate | F3: Install rate | G3: Supply | H3: Install | I3: Total | J3: Source / note
A4: 6.1 | B4: Dryvit Primus M base coat 25 kg | C4: 3 | D4: pail | E4: 23.18 | F4: 0 | G4: =C4*E4 | H4: =C4*F4 | I4: =G4+H4 | J4: SAP PRIMUS M 25 kg
A5: 6.2 | B5: Dryvit Standard Plus mesh (laps incl.) | C5: 60.77 | D5: m2 | E5: 1.33 | F5: 0 | G5: =C5*E5 | H5: =C5*F5 | I5: =G5+H5 | J5: SAP Standard Plus mesh 50 m2 roll 66.73
A6: 6.3 | B6: Dryvit Color Prime Plus 4 gal | C6: 3 | D6: pail | E6: 51.79 | F6: 0 | G6: =C6*E6 | H6: =C6*F6 | I6: =G6+H6 | J6: SAP Color Prime Plus 4 gal
A7: 6.4 | B7: Dryvit PMR Sandpebble finish 24.72 kg | C7: 5 | D7: pail | E7: 59.9 | F7: 0 | G7: =C7*E7 | H7: =C7*F7 | I7: =G7+H7 | J7: SAP PMR Sandpebble 24.72 kg
A8: 6.5 | B8: Apply Dryvit 500 (base + mesh + prime + finish) | C8: 52.84 | D8: m2 | E8: 0 | F8: 25.5 | G8: =C8*E8 | H8: =C8*F8 | I8: =G8+H8 | J8: NGR Dryvit 0.75 h/m2
A9: 6.6 | B9: Dryvit beads (base, corner, stop, reveal) | C9: 96.5 | D9: m | E9: 1.3 | F9: 1.7 | G9: =C9*E9 | H9: =C9*F9 | I9: =G9+H9 | J9: SAP corner / stop / bellcast beads per 2.5 m (2.16-3.31)
H10: Bill total | I10: =SUM(I4:I9)

Sheet Bill 7
A1: DG-T06 Type 06 - Rendered double garage - Bill 7 - Opening schedule (doors + windows)
A3: Ref | B3: Item | C3: Qty | D3: Unit | E3: Supply rate | F3: Install rate | G3: Supply | H3: Install | I3: Total | J3: Source / note
A4: 7.1 | B4: L1-D01 Electric insulated roller garage door 4,800 x 2,286 S.O., RAL 7016: 77 slats, box behind the lintel course, guides, tubular motor, 2 remotes, manual override, brush seals | C4: 1 | D4: nr | E4: 2461.25 | F4: 272 | G4: =C4*E4 | H4: =C4*F4 | I4: =G4+H4 | J4: MKT electric insulated roller door 4.8 x 2.3; accessories GBP 11.25 incl.
A5: 7.2 | B5: L1-D02 Composite personnel door 900 x 2,286 S.O.: frame, fixed overpanel, multipoint lock, lever handles, low threshold; illbruck ME110 internal membrane (5.5 m) + sealant | C5: 1 | D5: nr | E5: 1067.94 | F5: 184.96 | G5: =C5*E5 | H5: =C5*F5 | I5: =G5+H5 | J5: NGR single door (composite + overpanel); accessories GBP 17.94 incl.
A6: 7.3 | B6: L1-W01 Alu-clad timber window 1,200 x 914 S.O., RAL 7016, DGU, trickle vent, handles, aluminium cill; illbruck ME110 internal membrane (4.2 m) + sealant | C6: 1 | D6: nr | E6: 753.29 | F6: 113.56 | G6: =C6*E6 | H6: =C6*F6 | I6: =G6+H6 | J6: NGR 280 per window + 420/m2 (base on the window line); accessories GBP 12.43 incl.
A7: 7.4 | B7: L1-W02 Alu-clad timber window 1,200 x 914 S.O., RAL 7016, DGU, trickle vent, handles, aluminium cill; illbruck ME110 internal membrane (4.2 m) + sealant | C7: 1 | D7: nr | E7: 753.29 | F7: 113.56 | G7: =C7*E7 | H7: =C7*F7 | I7: =G7+H7 | J7: NGR 280 per window + 420/m2 (base on the window line); accessories GBP 12.43 incl.
H8: Bill total | I8: =SUM(I4:I7)

Sheet Bill 8
A1: DG-T06 Type 06 - Rendered double garage - Bill 8 - Electrical installation
A3: Ref | B3: Item | C3: Qty | D3: Unit | E3: Supply rate | F3: Install rate | G3: Supply | H3: Install | I3: Total | J3: Source / note
A4: 8.1 | B4: 4 double sockets + 4 LED battens, sub-board, short feed, test + cert | C4: 1 | D4: item | E4: 760 | F4: 680 | G4: =C4*E4 | H4: =C4*F4 | I4: =G4+H4 | J4: TLS / MKT 4 + 4
H5: Bill total | I5: =SUM(I4:I4)

Sheet Bill 9
A1: DG-T06 Type 06 - Rendered double garage - Bill 9 - Design + approvals (provisional)
A3: Ref | B3: Item | C3: Qty | D3: Unit | E3: Supply rate | F3: Install rate | G3: Supply | H3: Install | I3: Total | J3: Source / note
A4: 9.1 | B4: Building control (provisional) | C4: 1 | D4: item | E4: 650 | F4: 0 | G4: =C4*E4 | H4: =C4*F4 | I4: =G4+H4 | J4: Building control (LABC) - provisional
A5: 9.2 | B5: Structural engineer - calcs + details (provisional) | C5: 1 | D5: item | E5: 850 | F5: 0 | G5: =C5*E5 | H5: =C5*F5 | I5: =G5+H5 | J5: Structural engineer calcs - provisional
A6: 9.3 | B6: Drawings / lawful development certificate (provisional) | C6: 1 | D6: item | E6: 1250 | F6: 0 | G6: =C6*E6 | H6: =C6*F6 | I6: =G6+H6 | J6: Drawings / PD certificate / planning - provisional
H7: Bill total | I7: =SUM(I4:I6)
